Workbook

Sheet Session_NOT_matched_to_nlc_reg
A1: export_id | B1: match_type | C1: match_by | D1: Flocknote ID | E1: First Name | F1: Last Name | G1: Confirmation Number | H1: Gender Identity, Homosexuality, and Same Sex Attraction Dialogue | I1: Contraception/IVF/Abortion Dialogue | J1: Immigration Dialogue | K1: Signed Up Date
A2: export_34580ee0c2ad | E2: Dave | F2: Guirao | G2: Q8TH7 | I2: X | K2: 46048.52 | L2: Duplicate
A3: export_aace8726b921 | D3: F-C3NM62 | E3: Vince Claudette | F3: WEST | G3: G8ZT7 | H3: X | K3: 46054.869
A4: export_fd6284622379 | D4: F-H2PC33 | E4: Mel Tess | F4: Ebrada | G4: J86V9 | J4: X | K4: 46058.753 | L4: Duplicate

Sheet Session_matched_to_nlc_reg
A1: nlc_id | B1: match_type | C1: match_by | D1: Flocknote ID | E1: First Name | F1: Last Name | G1: Confirmation Number | H1: Gender Identity, Homosexuality, and Same Sex Attraction Dialogue | I1: Contraception/IVF/Abortion Dialogue | J1: Immigration Dialogue | K1: Signed Up Date | L1: NLC Name | M1: NLC Last Name | N1: NLC Email
A2: nlc_5926f7f983b4 | B2: exact_match | C2: name | D2: F-P9NK5C | E2: Pura | F2: Abadejos | G2: X96N6 | J2: X | K2: 46061.172 | L2: =VLOOKUP(A2,nlc_registration!A:G,5,0) -> Pura | M2: =VLOOKUP(A2,nlc_registration!A:G,6,0) -> Abadejos | N2: =VLOOKUP(A2,nlc_registration!A:G,7,0) -> pura_abdjs@yahoo.com
A3: nlc_ab1b2ba021fd | B3: exact_match | C3: name | D3: F-N2VZ7L | E3: Dylyn | F3: Abella | G3: L5CV7 | H3: X | K3: 46058.799 | L3: =VLOOKUP(A3,nlc_registration!A:G,5,0) -> Dylyn | M3: =VLOOKUP(A3,nlc_registration!A:G,6,0) -> Abella | N3: =VLOOKUP(A3,nlc_registration!A:G,7,0) -> abelladylyn@gmail.com
A4: nlc_09d58ed2c463 | B4: exact_match | C4: name | D4: F-G4TX3G | E4: Joanna | F4: Ablaza | G4: J25H8 | J4: X | K4: 46058.892 | L4: =VLOOKUP(A4,nlc_registration!A:G,5,0) -> Joanna | M4: =VLOOKUP(A4,nlc_registration!A:G,6,0) -> Ablaza | N4: =VLOOKUP(A4,nlc_registration!A:G,7,0) -> joanna.ablaza@gmail.com
A5: nlc_2212a8322395 | B5: exact_match | C5: name | D5: F-N9XH3Z | E5: Melvin | F5: Ablaza | G5: J46W6 | H5: X | K5: 46058.801 | L5: =VLOOKUP(A5,nlc_registration!A:G,5,0) -> Melvin | M5: =VLOOKUP(A5,nlc_registration!A:G,6,0) -> Ablaza | N5: =VLOOKUP(A5,nlc_registration!A:G,7,0) -> mablaza@gmail.com
A6: nlc_e6a68626aa7e | B6: exact_match | C6: name | D6: F-G8TK7M | E6: Duane | F6: Absuelo | G6: T37M4 | H6: X | K6: 46062.733 | L6: =VLOOKUP(A6,nlc_registration!A:G,5,0) -> DUANE | M6: =VLOOKUP(A6,nlc_registration!A:G,6,0) -> ABSUELO | N6: =VLOOKUP(A6,nlc_registration!A:G,7,0) -> duane.absuelo@couplesforchristusa.org
A7: nlc_2c877ac58dce | B7: exact_match | C7: name | D7: F-W9PF8K | E7: VIVIENNE | F7: ABSUELO | G7: D5VL8 | H7: X | K7: 46062.764 | L7: =VLOOKUP(A7,nlc_registration!A:G,5,0) -> VIVIENNE | M7: =VLOOKUP(A7,nlc_registration!A:G,6,0) -> ABSUELO | N7: =VLOOKUP(A7,nlc_registration!A:G,7,0) -> absuelovivienne@yahoo.com
A8: nlc_f13acc28e4b3 | B8: exact_match | C8: name | D8: F-Q3QM7P | E8: Norma | F8: Acebo | G8: Z72V2 | H8: X | K8: 46048.56 | L8: =VLOOKUP(A8,nlc_registration!A:G,5,0) -> Norma | M8: =VLOOKUP(A8,nlc_registration!A:G,6,0) -> Acebo | N8: =VLOOKUP(A8,nlc_registration!A:G,7,0) -> nacebo1118@gmail.com
A9: nlc_d43b2f9ed4f9 | B9: exact_match | C9: name | D9: F-F3JH2F | E9: Pamela | F9: Acebo | G9: M5XV2 | J9: X | K9: 46063.984 | L9: =VLOOKUP(A9,nlc_registration!A:G,5,0) -> Pamela | M9: =VLOOKUP(A9,nlc_registration!A:G,6,0) -> Acebo | N9: =VLOOKUP(A9,nlc_registration!A:G,7,0) -> spacebo@gmail.com
A10: nlc_e6ec2da492a6 | B10: exact_match | C10: name | D10: F-H75G39 | E10: Steven | F10: Acebo | G10: M5XV2 | J10: X | K10: 46063.984 | L10: =VLOOKUP(A10,nlc_registration!A:G,5,0) -> Steven | M10: =VLOOKUP(A10,nlc_registration!A:G,6,0) -> Acebo | N10: =VLOOKUP(A10,nlc_registration!A:G,7,0) -> spacebo@gmail.com
A11: nlc_5e024e432309 | B11: exact_match | C11: name | D11: F-P58F7N | E11: Nilo | F11: Alazas | G11: G7CS2 | H11: X | K11: 46070.376 | L11: =VLOOKUP(A11,nlc_registration!A:G,5,0) -> Nilo | M11: =VLOOKUP(A11,nlc_registration!A:G,6,0) -> Alazas | N11: =VLOOKUP(A11,nlc_registration!A:G,7,0) -> niloalazas@gmail.com
A12: nlc_859e65c3f5e3 | B12: exact_match | C12: name | D12: F-Q4KG2R | E12: Raul | F12: Alcaraz | G12: X8GG8 | H12: X | K12: 46048.672 | L12: =VLOOKUP(A12,nlc_registration!A:G,5,0) -> Raul | M12: =VLOOKUP(A12,nlc_registration!A:G,6,0) -> Alcaraz | N12: =VLOOKUP(A12,nlc_registration!A:G,7,0) -> raulgigicfcy@gmail.com
A13: nlc_4360b21d37ff | B13: exact_match | C13: name | D13: F-N2DQ43 | E13: ALEX | F13: ALGARME | G13: F8ZT9 | I13: X | K13: 46051.777 | L13: =VLOOKUP(A13,nlc_registration!A:G,5,0) -> Alex | M13: =VLOOKUP(A13,nlc_registration!A:G,6,0) -> Algarme | N13: =VLOOKUP(A13,nlc_registration!A:G,7,0) -> alex.algarme@couplesforchristusa.org
A14: nlc_d66ca3e5fde5 | B14: exact_match | C14: name | E14: Enely | F14: Algarme | G14: F8ZT9 | I14: X | K14: 46051.777 | L14: =VLOOKUP(A14,nlc_registration!A:G,5,0) -> Enely | M14: =VLOOKUP(A14,nlc_registration!A:G,6,0) -> Algarme | N14: =VLOOKUP(A14,nlc_registration!A:G,7,0) -> enelyalgarme@yahoo.com
A15: nlc_2db568bc97a6 | B15: exact_match | C15: name | D15: F-T5WS83 | E15: DODJIE | F15: ALLAREY | G15: V28S9 | J15: X | K15: 46067.788 | L15: =VLOOKUP(A15,nlc_registration!A:G,5,0) -> DOdjie | M15: =VLOOKUP(A15,nlc_registration!A:G,6,0) -> ALLAREY | N15: =VLOOKUP(A15,nlc_registration!A:G,7,0) -> dodjie.allarey@couplesforchristusa.org
A16: nlc_463908e2f5b0 | B16: exact_match | C16: name | D16: F-N7HZ8K | E16: Judy | F16: Allarey | G16: R84R5 | J16: X | K16: 46069.305 | L16: =VLOOKUP(A16,nlc_registration!A:G,5,0) -> Judy | M16: =VLOOKUP(A16,nlc_registration!A:G,6,0) -> Allarey | N16: =VLOOKUP(A16,nlc_registration!A:G,7,0) -> judy.allarey@couplesforchristusa.org
A17: nlc_f82adac1b306 | B17: exact_match | C17: name | D17: F-P8ZD8P | E17: helen | F17: ancheta | G17: M35C7 | H17: X | K17: 46058.815 | L17: =VLOOKUP(A17,nlc_registration!A:G,5,0) -> helen | M17: =VLOOKUP(A17,nlc_registration!A:G,6,0) -> ancheta | N17: =VLOOKUP(A17,nlc_registration!A:G,7,0) -> vernon_helen@yahoo.ckm
A18: nlc_39d7dc350eec | B18: exact_match | C18: name | D18: F-X6RV95 | E18: vernon | F18: ancheta | G18: F76W3 | J18: X | K18: 46067.322 | L18: =VLOOKUP(A18,nlc_registration!A:G,5,0) -> vernon | M18: =VLOOKUP(A18,nlc_registration!A:G,6,0) -> ancheta | N18: =VLOOKUP(A18,nlc_registration!A:G,7,0) -> vernon_helen@yahoo.com
A19: nlc_034fee7ba0c5 | B19: exact_match | C19: name | D19: F-Z9VK3K | E19: ALDEN | F19: ARCOS | G19: L9KW4 | J19: X | K19: 46061.824 | L19: =VLOOKUP(A19,nlc_registration!A:G,5,0) -> ALDEN | M19: =VLOOKUP(A19,nlc_registration!A:G,6,0) -> ARCOS | N19: =VLOOKUP(A19,nlc_registration!A:G,7,0) -> alden315@msn.com
A20: nlc_9f1f286c6b48 | B20: exact_match | C20: name | D20: F-S3WQ73 | E20: Lilian | F20: Austria | G20: W95V9 | I20: X | K20: 46058.801 | L20: =VLOOKUP(A20,nlc_registration!A:G,5,0) -> Lilian | M20: =VLOOKUP(A20,nlc_registration!A:G,6,0) -> Austria | N20: =VLOOKUP(A20,nlc_registration!A:G,7,0) -> lilianaustria4@gmail.com
A21: nlc_0f516f01cbc1 | B21: exact_match | C21: name | D21: F-H6CB5K | E21: JOSEPHINE | F21: Baisac | G21: V46N8 | H21: X | K21: 46048.361 | L21: =VLOOKUP(A21,nlc_registration!A:G,5,0) -> Josephine | M21: =VLOOKUP(A21,nlc_registration!A:G,6,0) -> Baisac | N21: =VLOOKUP(A21,nlc_registration!A:G,7,0) -> baisacjosephine@yahoo.com
A22: nlc_e89d6d394b12 | B22: exact_match | C22: name | D22: F-G2ZP3S | E22: Jerry | F22: Balansag | G22: Q78K6 | H22: X | K22: 46067.712 | L22: =VLOOKUP(A22,nlc_registration!A:G,5,0) -> Jerry | M22: =VLOOKUP(A22,nlc_registration!A:G,6,0) -> Balansag | N22: =VLOOKUP(A22,nlc_registration!A:G,7,0) -> jerryb1031@live.con
A23: nlc_121e7c91a67d | B23: exact_match | C23: name | D23: F-M36Q79 | E23: Michelle | F23: Balansag | G23: B7WC4 | J23: X | K23: 46067.708 | L23: =VLOOKUP(A23,nlc_registration!A:G,5,0) -> Michelle | M23: =VLOOKUP(A23,nlc_registration!A:G,6,0) -> Balansag | N23: =VLOOKUP(A23,nlc_registration!A:G,7,0) -> mykel818@hotmail.com
A24: nlc_2f740be488dd | B24: exact_match | C24: name | D24: F-F3HM3R | E24: Joy | F24: Banasan | G24: J2PD4 | H24: X | K24: 46058.798 | L24: =VLOOKUP(A24,nlc_registration!A:G,5,0) -> Joy | M24: =VLOOKUP(A24,nlc_registration!A:G,6,0) -> Banasan | N24: =VLOOKUP(A24,nlc_registration!A:G,7,0) -> pjbanasan@gmail.com
A25: nlc_71ad212572d6 | B25: exact_match | C25: name | D25: F-D64X6X | E25: PIDZ | F25: BANASAN | G25: X48F4 | J25: X | K25: 46060.91 | L25: =VLOOKUP(A25,nlc_registration!A:G,5,0) -> Pidz | M25: =VLOOKUP(A25,nlc_registration!A:G,6,0) -> Banasan | N25: =VLOOKUP(A25,nlc_registration!A:G,7,0) -> pjbanasan@gmail.com
A26: nlc_565d240f5343 | B26: exact_match | C26: name | E26: thpob77@gmail.com | G26: B76W4 | J26: X | K26: 46059.933 | L26: =VLOOKUP(A26,nlc_registration!A:G,5,0) -> 0 | M26: =VLOOKUP(A26,nlc_registration!A:G,6,0) -> 0 | N26: =VLOOKUP(A26,nlc_registration!A:G,7,0) -> 0
A27: nlc_98e80b7604ce | B27: exact_match | C27: name | D27: F-X3DN89 | E27: Arthur | F27: Barlaan | G27: N5RK8 | I27: X | K27: 46057.831 | L27: =VLOOKUP(A27,nlc_registration!A:G,5,0) -> Arthur | M27: =VLOOKUP(A27,nlc_registration!A:G,6,0) -> Barlaan | N27: =VLOOKUP(A27,nlc_registration!A:G,7,0) -> arthurbarlaan@couplesforchristflorida.org
A28: nlc_588243224bda | B28: exact_match | C28: name | D28: F-W3BJ8P | E28: Joy | F28: Barlaan | G28: G2TZ5 | H28: X | K28: 46057.833 | L28: =VLOOKUP(A28,nlc_registration!A:G,5,0) -> Joy | M28: =VLOOKUP(A28,nlc_registration!A:G,6,0) -> Barlaan | N28: =VLOOKUP(A28,nlc_registration!A:G,7,0) -> joylb59@gmail.com
A29: nlc_d1ef9f5ba94d | B29: exact_match | C29: name | D29: F-V2WL36 | E29: Chay | F29: Barrios | G29: W57D5 | H29: X | K29: 46061.426 | L29: =VLOOKUP(A29,nlc_registration!A:G,5,0) -> Chay | M29: =VLOOKUP(A29,nlc_registration!A:G,6,0) -> Barrios | N29: =VLOOKUP(A29,nlc_registration!A:G,7,0) -> chaybarrios@gmail.com
A30: nlc_d7ab8231122a | B30: exact_match | C30: name | D30: F-R79L79 | E30: Orlando | F30: Batongbakal | G30: B7BR5 | J30: X | K30: 46059.151 | L30: =VLOOKUP(A30,nlc_registration!A:G,5,0) -> Orlando | M30: =VLOOKUP(A30,nlc_registration!A:G,6,0) -> Batongbakal | N30: =VLOOKUP(A30,nlc_registration!A:G,7,0) -> orlybaton@gmail.com
A31: nlc_f2d383817aa3 | B31: exact_match | C31: name | D31: F-F6KC4F | E31: Arnel | F31: Bautista | G31: R69H4 | H31: X | K31: 46059.464 | L31: =VLOOKUP(A31,nlc_registration!A:G,5,0) -> Arnel | M31: =VLOOKUP(A31,nlc_registration!A:G,6,0) -> Bautista | N31: =VLOOKUP(A31,nlc_registration!A:G,7,0) -> avbautista@yahoo.com
A32: nlc_f2dd3c141e67 | B32: exact_match | C32: name | E32: Joy | F32: Bautista | G32: R69H4 | H32: X | K32: 46059.464 | L32: =VLOOKUP(A32,nlc_registration!A:G,5,0) -> Joy | M32: =VLOOKUP(A32,nlc_registration!A:G,6,0) -> Bautista | N32: =VLOOKUP(A32,nlc_registration!A:G,7,0) -> jdlbautista@gmail.com
A33: nlc_90a62c02a29c | B33: exact_match | C33: name | D33: F-D46N4D | E33: Imelda | F33: Beltran | G33: S9ZT5 | I33: X | K33: 46058.843 | L33: =VLOOKUP(A33,nlc_registration!A:G,5,0) -> Imelda | M33: =VLOOKUP(A33,nlc_registration!A:G,6,0) -> Beltran | N33: =VLOOKUP(A33,nlc_registration!A:G,7,0) -> bima83@att.net
A34: nlc_5d7b7acb182e | B34: exact_match | C34: name | D34: F-J38R9K | E34: Mike | F34: Bermudo | G34: X8RG5 | H34: X | K34: 46048.446 | L34: =VLOOKUP(A34,nlc_registration!A:G,5,0) -> Mike | M34: =VLOOKUP(A34,nlc_registration!A:G,6,0) -> Bermudo | N34: =VLOOKUP(A34,nlc_registration!A:G,7,0) -> mike.bermudo@gmail.com
A35: nlc_6471b52eb458 | B35: exact_match | C35: name | E35: Ayrah | F35: Bermudo | G35: X8RG5 | H35: X | K35: 46048.446 | L35: =VLOOKUP(A35,nlc_registration!A:G,5,0) -> Ayrah | M35: =VLOOKUP(A35,nlc_registration!A:G,6,0) -> Bermudo | N35: =VLOOKUP(A35,nlc_registration!A:G,7,0) -> ayrahbermudo1@gmail.com
A36: nlc_bc70c297ca36 | B36: exact_match | C36: name | D36: F-Q3HR2F | E36: Neldred | F36: Bracamonte | G36: S5CW4 | I36: X | K36: 46058.847 | L36: =VLOOKUP(A36,nlc_registration!A:G,5,0) -> Neldred | M36: =VLOOKUP(A36,nlc_registration!A:G,6,0) -> Bracamonte | N36: =VLOOKUP(A36,nlc_registration!A:G,7,0) -> littlebrax@yahoo.com
A37: nlc_2ad8e4fb06a7 | B37: exact_match | C37: name | D37: F-T5RL7R | E37: Val | F37: Bracamonte | G37: P2ZX6 | J37: X | K37: 46068.688 | L37: =VLOOKUP(A37,nlc_registration!A:G,5,0) -> Val | M37: =VLOOKUP(A37,nlc_registration!A:G,6,0) -> Bracamonte | N37: =VLOOKUP(A37,nlc_registration!A:G,7,0) -> val_brax@yahoo.com
A38: nlc_baca07483e40 | B38: exact_match | C38: name | D38: F-T2WZ4W | E38: Lorraine | F38: Buhay | G38: P9XZ9 | H38: X | K38: 46067.712 | L38: =VLOOKUP(A38,nlc_registration!A:G,5,0) -> Lorraine | M38: =VLOOKUP(A38,nlc_registration!A:G,6,0) -> Buhay | N38: =VLOOKUP(A38,nlc_registration!A:G,7,0) -> cincodmayo@gmail.com
A39: nlc_ee909c455df1 | B39: exact_match | C39: name | D39: F-V4QS98 | E39: Shirley | F39: Cabrera | G39: R8SJ5 | H39: X | K39: 46048.747 | L39: =VLOOKUP(A39,nlc_registration!A:G,5,0) -> Shirley | M39: =VLOOKUP(A39,nlc_registration!A:G,6,0) -> Cabrera | N39: =VLOOKUP(A39,nlc_registration!A:G,7,0) -> shirley@thecabreradesigngroup.com
A40: nlc_bd00ba091a3d | B40: exact_match | C40: name | D40: F-B4PG7C | E40: LUCIA | F40: CACHERO | G40: V6BW9 | H40: X | K40: 46062.371 | L40: =VLOOKUP(A40,nlc_registration!A:G,5,0) -> Lucia | M40: =VLOOKUP(A40,nlc_registration!A:G,6,0) -> Cachero | N40: =VLOOKUP(A40,nlc_registration!A:G,7,0) -> lucia_cachero@yahoo.com
...

Sheet nlc_registration
A1: id | B1: match_type | C1: match_by_comment | D1: Registrant - Amount | E1: Registrant - Person's Name - First Name | F1: Registrant - Person's Name - Last Name | G1: Registrant - Email | H1: Registrant - Phone Number | I1: Registrant - Allergies & Special Need | J1: Registrant - SubTotal | K1: Region | L1: Region - Other Text | M1: Ministry Membership | N1: Service | O1: Have Kids to register for KidsZone? (Ages 4 - 12 yrs old) | P1: How Many Kids for Kidswatch? | Q1: Billing Discount Code | R1: Administrative Fee | S1: Total Amount | T1: Billing Name | U1: Billing Address Line 1 | V1: Billing Zip | W1: Billing Email Address | X1: Billing Phone Number | Y1: Paid | Z1: Paid | AA1: Transaction ID | AB1: Transaction Result | AC1: Transaction Message | AD1: Created At | AE1: NOTES | AF1: export_Flocknote_ID | AG1: export_First_Name | AH1: export_Last_Name | AI1: export_Confirmation_Number | AJ1: export_Gender_Identity_Dialogue | AK1: export_Contraception_Dialogue | AL1: export_Immigration_Dialogue | AM1: export_Signed_Up_Date
A2: nlc_5ef4b888e524 | D2: 50 | E2: Amid | F2: Lauro | AE2: Zelle Payment
A3: nlc_3141ca6d40ea | D3: 50 | E3: Cristina | F3: Baltazar | AE3: Zelle Payment
A4: nlc_7862b50e15ac | D4: 50 | E4: Cris | F4: Baltazar | AE4: Zelle Payment
A5: nlc_2301d89035a5 | D5: 50 | E5: Eric | F5: Villanueva | AE5: Zelle Payment
A6: nlc_6ceb8554b66d | D6: 50 | E6: Pat | F6: Villanueva | AE6: Zelle Payment
A7: nlc_a22677264385 | D7: 50 | E7: Ricky | F7: Coronel | G7: rcor950825@aol.com | H7: 949-929-1586 | J7: 0 | K7: SOUTHWEST B (Arizona, Colorado, New Mexico, Southern California) | M7: CFC | N7: Others (GOL, CRO, Ablaze, Etc) | O7: No | Q7: NLC!2026 | S7: 0 | Y7: 0 | Z7: 0 | AD7: 46057.641 | AE7: Bro Ricky to pay by check
A8: nlc_8d4943aa4885 | D8: 50 | E8: Binky | F8: Coronel | H8: 949-929-1586 | J8: 0 | K8: SOUTHWEST B (Arizona, Colorado, New Mexico, Southern California) | M8: CFC | N8: Others (GOL, CRO, Ablaze, Etc) | O8: No | Q8: NLC!2026 | S8: 0 | Y8: 0 | Z8: 0 | AD8: 46057.641 | AE8: Bro Ricky to pay by check
A9: nlc_22ae97a16d98 | D9: 50 | E9: Karen | F9: Aguilar | AE9: Zelle Payment
A10: nlc_3528d7875f70 | D10: 50 | E10: David Jr. | F10: Aguilar | AE10: Zelle Payment
A11: nlc_0602a801f1a4 | B11: possible_match | C11: possible match by lastname (matched to NLC with no match) | D11: 50 | E11: Wilma | F11: Santos | AE11: Zelle Payment | AF11: F-M6PD6L | AG11: MARIA ANGELICA | AH11: SANTOS | AI11: V65G6 | AJ11: X | AM11: 46069.994
A12: nlc_3dcc80e6dd58 | D12: 50 | E12: Robert | F12: Santios | AE12: Zelle Payment
A13: nlc_53cf3909cb95 | B13: exact_match | C13: exact_match: email or first+last name | D13: 50 | E13: Carmela | F13: Panadero | AE13: Zelle Payment | AF13: F-M9CX3C | AG13: Carmela | AH13: Panadero | AI13: D77P9 | AL13: X | AM13: 46058.81
A14: nlc_c66aaa3ff136 | D14: 50 | E14: Leo | F14: Panadero | AE14: Zelle Payment
A15: nlc_c9785ae16ed7 | B15: possible_match | C15: possible match by lastname (only one NLC with no match) | D15: 50 | E15: Lily | F15: Halili | AE15: Zelle Payment | AG15: Lily P. | AH15: Halili | AI15: F2CV3 | AL15: X | AM15: 46069.47
A16: nlc_4dc8da1f4b2a | B16: exact_match | C16: exact_match: email or first+last name | D16: 50 | E16: Buddy | F16: Halili | AE16: Zelle Payment | AF16: F-H5MP9V | AG16: Buddy | AH16: Halili | AI16: F2CV3 | AL16: X | AM16: 46069.47
A17: nlc_daadb3f781ae | D17: 50 | E17: Joy | F17: De Guzman | G17: joydeguzman@comcast.net | AE17: Zelle Payment
A18: nlc_14ced67448ae | D18: 50 | E18: Ding | F18: De Guzman | G18: dingcfc.ca@hotmail.com | AE18: Zelle Payment
A19: nlc_4c8187d39c46 | D19: 50 | E19: Geraldine | F19: Visarra | G19: vincentvisarra70@gmail.com | AE19: Zelle Payment
A20: nlc_c749b41ed50b | D20: 50 | E20: Vincent | F20: Visarra | G20: vincent.visarra@couplesforchristusa.org | AE20: Zelle Payment
A21: nlc_e5dc8d7d2519 | D21: 50 | E21: Hugo | F21: Mendoza | H21: 949-929-1586 | J21: 0 | K21: SOUTHWEST A (Alaska, Hawaii, Northern California, North Nevada) | M21: CFC | N21: Others (GOL, CRO, Ablaze, Etc) | O21: No | Q21: NLC!2026 | S21: 0 | Y21: 0 | Z21: 0 | AD21: 46057.633 | AE21: Zelle pmt from bCarlos Jacinto (PPC)
A22: nlc_f2ea3451e215 | D22: 50 | E22: Javier | F22: Queipo | H22: 949-929-1586 | J22: 0 | K22: SOUTHWEST A (Alaska, Hawaii, Northern California, North Nevada) | M22: CFC | N22: Others (GOL, CRO, Ablaze, Etc) | O22: No | Q22: NLC!2026 | S22: 0 | Y22: 0 | Z22: 0 | AD22: 46057.632 | AE22: Zelle pmt from bCarlos Jacinto (PPC)
A23: nlc_1db848c5e2d4 | D23: 50 | E23: Omaira | F23: Queipo | H23: 949-929-1586 | J23: 0 | K23: SOUTHWEST A (Alaska, Hawaii, Northern California, North Nevada) | M23: CFC | N23: Others (GOL, CRO, Ablaze, Etc) | O23: No | Q23: NLC!2026 | S23: 0 | Y23: 0 | Z23: 0 | AD23: 46057.632 | AE23: Zelle pmt from bCarlos Jacinto (PPC)
A24: nlc_d81a699fedc8 | B24: exact_match | C24: exact_match: email or first+last name | D24: 50 | E24: Carlos | F24: Garcia | H24: 949-929-1586 | J24: 0 | K24: SOUTHWEST A (Alaska, Hawaii, Northern California, North Nevada) | M24: CFC | N24: Others (GOL, CRO, Ablaze, Etc) | O24: No | Q24: NLC!2026 | S24: 0 | Y24: 0 | Z24: 0 | AD24: 46057.631 | AE24: Zelle pmt from bCarlos Jacinto (PPC) | AF24: F-Z7KM9J | AG24: Carlos | AH24: Garcia | AI24: W9DJ6 | AL24: X | AM24: 46070.795
A25: nlc_581585ff7f09 | B25: exact_match | C25: exact_match: email or first+last name | D25: 50 | E25: Julie | F25: Garcia | H25: 949-929-1586 | J25: 0 | K25: SOUTHWEST A (Alaska, Hawaii, Northern California, North Nevada) | M25: CFC | N25: Others (GOL, CRO, Ablaze, Etc) | O25: No | Q25: NLC!2026 | S25: 0 | Y25: 0 | Z25: 0 | AD25: 46057.631 | AE25: Zelle pmt from bCarlos Jacinto (PPC) | AF25: F-W6VD5N | AG25: Julie | AH25: Garcia | AI25: V8CM8 | AL25: X | AM25: 46064.901
A26: nlc_1d7560e62803 | D26: 50 | E26: Jose | F26: Rincon | H26: 949-929-1586 | J26: 0 | K26: SOUTHWEST A (Alaska, Hawaii, Northern California, North Nevada) | M26: CFC | N26: CFC (HH & up) | O26: No | Q26: NLC!2026 | S26: 0 | Y26: 0 | Z26: 0 | AD26: 46057.63 | AE26: Zelle pmt from bCarlos Jacinto (PPC)
A27: nlc_95bed6f1a8b0 | D27: 50 | E27: Maria | F27: Rincon | H27: 949-929-1586 | J27: 0 | K27: SOUTHWEST A (Alaska, Hawaii, Northern California, North Nevada) | M27: CFC | N27: CFC (HH & up) | O27: No | Q27: NLC!2026 | S27: 0 | Y27: 0 | Z27: 0 | AD27: 46057.63 | AE27: Zelle pmt from bCarlos Jacinto (PPC)
A28: nlc_a5b426782017 | D28: 50 | E28: Marco | F28: Torres | H28: 949-929-1586 | J28: 0 | K28: SOUTHWEST A (Alaska, Hawaii, Northern California, North Nevada) | M28: CFC | N28: CFC (HH & up) | O28: No | Q28: NLC!2026 | S28: 0 | Y28: 0 | Z28: 0 | AD28: 46057.628 | AE28: Zelle pmt from bCarlos Jacinto (PPC)
A29: nlc_aab532323b39 | D29: 50 | E29: Catalina | F29: Torres | H29: 949-929-1586 | J29: 0 | K29: SOUTHWEST A (Alaska, Hawaii, Northern California, North Nevada) | M29: CFC | N29: CFC (HH & up) | O29: No | Q29: NLC!2026 | S29: 0 | Y29: 0 | Z29: 0 | AD29: 46057.628 | AE29: Zelle pmt from bCarlos Jacinto (PPC)
A30: nlc_cd40677d30a4 | B30: possible_match | C30: possible match by lastname (matched to NLC with no match) | D30: 50 | E30: Tony | F30: Jacinto | H30: 949-929-1586 | J30: 0 | K30: SOUTHWEST A (Alaska, Hawaii, Northern California, North Nevada) | M30: CFC | N30: Family Ministries (HOLD, SOLD, SFC, CFCY, KFC) | O30: No | Q30: NLC!2026 | S30: 0 | Y30: 0 | Z30: 0 | AD30: 46057.627 | AE30: Zelle pmt from bCarlos Jacinto (PPC) | AF30: F-F8VT9R | AG30: Carlos Elena | AH30: JACINTO | AI30: V2RD8 | AL30: X | AM30: 46056.347
A31: nlc_f2f8d4a99ab2 | D31: 50 | E31: Celina | F31: Jacinto | H31: 949-929-1586 | J31: 0 | K31: SOUTHWEST A (Alaska, Hawaii, Northern California, North Nevada) | M31: CFC | N31: Family Ministries (HOLD, SOLD, SFC, CFCY, KFC) | O31: No | Q31: NLC!2026 | S31: 0 | Y31: 0 | Z31: 0 | AD31: 46057.627 | AE31: Zelle pmt from bCarlos Jacinto (PPC)
A32: nlc_df123451dd2f | D32: 50 | E32: Sonny | F32: Santillan | G32: sonnysantillan@yahoo.com | H32: 949-929-1586 | J32: 0 | K32: SOUTHWEST A (Alaska, Hawaii, Northern California, North Nevada) | M32: CFC | N32: CFC (HH & up) | O32: No | Q32: NLC!2026 | S32: 0 | Y32: 0 | Z32: 0 | AD32: 46057.624 | AE32: Zelle pmt from bJun Ilagan
A33: nlc_eadef15d2022 | D33: 50 | E33: Jhonadel | F33: Santillan | G33: sonnyjhonde0728@gmail.com | H33: 949-929-1586 | J33: 0 | K33: SOUTHWEST A (Alaska, Hawaii, Northern California, North Nevada) | M33: CFC | N33: CFC (HH & up) | O33: No | Q33: NLC!2026 | S33: 0 | Y33: 0 | Z33: 0 | AD33: 46057.624 | AE33: Zelle pmt from bJun Ilagan
A34: nlc_fc9e2cd79854 | D34: 50 | E34: Paul | F34: Bernadas | G34: paulacz_bernadas@yahoo.com | H34: 949-929-1586 | J34: 0 | K34: SOUTHWEST A (Alaska, Hawaii, Northern California, North Nevada) | M34: CFC | N34: CFC (HH & up) | O34: No | Q34: NLC!2026 | S34: 0 | Y34: 0 | Z34: 0 | AD34: 46057.621 | AE34: Zelle pmt from bJun Ilagan
A35: nlc_bb691129f01a | D35: 50 | E35: Cecile | F35: Bernadas | G35: celaipber2003@yahoo.com | H35: 949-929-1586 | J35: 0 | K35: SOUTHWEST A (Alaska, Hawaii, Northern California, North Nevada) | M35: CFC | N35: CFC (HH & up) | O35: No | Q35: NLC!2026 | S35: 0 | Y35: 0 | Z35: 0 | AD35: 46057.621 | AE35: Zelle pmt from bJun Ilagan
A36: nlc_f4f41fd2a1d7 | D36: 50 | E36: Ed | F36: Ebalobo | G36: eduardo.ebalobo@gmail.com | H36: 949-929-1586 | J36: 0 | K36: SOUTHWEST A (Alaska, Hawaii, Northern California, North Nevada) | M36: CFC | N36: CFC (HH & up) | O36: No | Q36: NLC!2026 | S36: 0 | Y36: 0 | Z36: 0 | AD36: 46057.619 | AE36: Zelle pmt from bJun Ilagan
A37: nlc_b2280eafa40d | D37: 50 | E37: Leomi | F37: Ebalobo | G37: leomi.ebalobo@couplesforchristusa.org | H37: 949-929-1586 | J37: 0 | K37: SOUTHWEST A (Alaska, Hawaii, Northern California, North Nevada) | M37: CFC | N37: CFC (HH & up) | O37: No | Q37: NLC!2026 | S37: 0 | Y37: 0 | Z37: 0 | AD37: 46057.619 | AE37: Zelle pmt from bJun Ilagan
A38: nlc_bd2ef00a8744 | B38: exact_match | C38: exact_match: email or first+last name | D38: 50 | E38: Pedro | F38: Coronel | G38: pedrocoronel@verizon.net | H38: 302-354-0171 | I38: None | J38: 50 | K38: SOUTHWEST C (Central California, South Nevada, Utah) | M38: CFC | N38: Family Ministries (HOLD, SOLD, SFC, CFCY, KFC) | O38: No | R38: 2.9 | S38: 102.9 | T38: Rebecca Coronel | U38: 8275 Skye Blue St | V38: Las Vegas, NV | W38: Bexcor@gmail.com | X38: 302-354-1759 | Y38: 102.9 | Z38: 102.9 | AA38: 546627925 | AB38: Ok | AC38: Approved | AD38: 46057.588 | AF38: F-L62T2Q | AG38: Pedro | AH38: Coronel | AI38: L2CW3 | AJ38: X | AM38: 46067.459
A39: nlc_6322e5d2e5a2 | B39: exact_match | C39: exact_match: email or first+last name | D39: 50 | E39: Rebecca | F39: Coronel | G39: bexcor@gmail.com | H39: 302-354-1759 | I39: None | J39: 50 | K39: SOUTHWEST C (Central California, South Nevada, Utah) | M39: CFC | N39: Family Ministries (HOLD, SOLD, SFC, CFCY, KFC) | O39: No | R39: 2.9 | S39: 102.9 | T39: Rebecca Coronel | U39: 8275 Skye Blue St | V39: Las Vegas, NV | W39: Bexcor@gmail.com | X39: 302-354-1759 | Y39: 102.9 | Z39: 102.9 | AA39: 546627925 | AB39: Ok | AC39: Approved | AD39: 46057.588 | AF39: F-N5RP8F | AG39: Rebecca | AH39: Coronel | AI39: T5ZG7 | AJ39: X | AM39: 46064.838
A40: nlc_3718e622abbd | D40: 50 | E40: Paul | F40: Ramos | G40: lapj1122@gmail.com | H40: 909-678-6982 | J40: 50 | K40: SOUTHWEST C (Central California, South Nevada, Utah) | M40: CFC | N40: Family Ministries (HOLD, SOLD, SFC, CFCY, KFC) | O40: Yes | P40: 2 | R40: 2.9 | S40: 102.9 | T40: Lourdes Angela Ramos | U40: 27447 Sycamore Creek Dr. | V40: 91354 | W40: lapj1122@gmail.com | X40: 909-678-6982 | Y40: 102.9 | Z40: 102.9 | AA40: 546624083 | AB40: Ok | AC40: Approved | AD40: 46057.586
...
